<?xml version="1.0"?>
<robot xmlns:xacro="http://ros.org/wiki/xacro">

<xacro:if value="${COGIMON_TORSO}" >

<xacro:property name="d" value="0.11" /> <!-- weight diameter -->
<xacro:property name="r" value="${d/2.}" /> <!-- weight radius -->
<xacro:property name="h" value="${3.0*0.02}" /> <!-- weight height, here we consider three discs -->
<xacro:property name="m" value="30.0" /> <!-- weight mass -->
<xacro:property name="z" value="0.2" /><!-- weight position -->

<!-- LINKS -->
<link name ="DWL">
    <inertial>
      <origin xyz="${3.9412845e+01*mmTom} ${3.1221526e-01*mmTom} ${5.6331027*mmTom} " rpy="0 0 0"/>
      <mass value="7.4182685e-01"/>
      <inertia ixx="${9.4437073e+02*mm2Tom2}"  ixy="${4.8511769*mm2Tom2}"  ixz="${1.0757639e+02*mm2Tom2}" iyy="${1.5988107e+03*mm2Tom2}" iyz="${-1.1047540e+01*mm2Tom2}" izz="${1.5042997e+03*mm2Tom2}" />
    </inertial>
    <visual>
      <origin xyz="0.0 0.0 0.0" rpy="0 0 0"/>
      <geometry name="DWL_visual">
        <mesh filename="package://cogimon_urdf/meshes/TorsoRoll.stl" scale="${mmTom} ${mmTom} ${mmTom}" />
      </geometry>
      <material name="dark_grey"/>
    </visual>
    <collision>
      <origin xyz="0.0 0.0 0.0" rpy="0 0 0"/>
      <geometry name="DWL_collision">
        <mesh filename="package://cogimon_urdf/meshes/simple/TorsoRoll.stl" scale="${mmTom} ${mmTom} ${mmTom}" />
      </geometry>             
    </collision>
</link>

<xacro:if value="${COGIMON_PENNACCHIO}" >
<link name ="weight">
     <inertial>
      <origin xyz="0 0 0 " rpy="0 0 0"/>
      <mass value="${m}"/>
      <inertia ixx="${(1./12.)*m*(3.*r*r+h*h)}"  ixy="0"  ixz="0" iyy="${(1./12.)*m*(3.*r*r+h*h)}" iyz="0" izz="${(m*r*r)/2.}" />
    </inertial>
    <visual>
      <origin rpy="0 0 0" xyz="0 0 0"/>
      <geometry>
       <cylinder length="${h}" radius="${r}"/>
      </geometry>
    </visual>
    <collision>
      <origin rpy="0 0 0" xyz="0 0 0"/>
      <geometry>
       <cylinder length="${h}" radius="${r}"/>
      </geometry>             
    </collision>
</link>

<link name ="pennacchio">
    <inertial>
      <origin xyz="${-3.4081174e-03*mmTom} ${-3.4081174e-03*mmTom} ${1.7247336e+02*mmTom} " rpy="0 0 0"/>
      <mass value="2.1651618"/>
      <inertia ixx="${4.5713534e+04*mm2Tom2}"  ixy="${1.9747985e-02*mm2Tom2}"  ixz="${5.9794097e-01*mm2Tom2}" iyy="${4.5712755e+04*mm2Tom2}" iyz="${-2.6722676e-01*mm2Tom2}" izz="${6.0311791e+02*mm2Tom2}" />
    </inertial>
    <visual>
      <origin xyz="0.0 0.0 0.0" rpy="0 0 0"/>
      <geometry name="pennacchio_visual">
        <mesh filename="package://cogimon_urdf/meshes/Pennacchio.stl" scale="${mmTom} ${mmTom} ${mmTom}" />
      </geometry>
      <material name="dark_grey"/>
    </visual>
    <collision>
      <origin xyz="0.0 0.0 0.0" rpy="0 0 0"/>
      <geometry name="pennacchio_collision">
        <mesh filename="package://cogimon_urdf/meshes/simple/Pennacchio.stl" scale="${mmTom} ${mmTom} ${mmTom}" />
      </geometry>             
    </collision>
</link>
</xacro:if>

<xacro:unless value="${COGIMON_PENNACCHIO}">
<link name ="DWLExt">
    <inertial>
      <origin xyz="${1.5386429e-03*mmTom} ${5.1668430e-02*mmTom} ${9.5210134e+01 *mmTom} " rpy="0 0 0"/>
      <mass value="9.6910635e-01"/>
      <inertia ixx="${3.0414870e+03*mm2Tom2}"  ixy="${-2.8413688*mm2Tom2}"  ixz="${9.6851038e+01*mm2Tom2}" iyy="${3.0465319e+03*mm2Tom2}" iyz="${-8.8025302*mm2Tom2}" izz="${1.5978729e+03*mm2Tom2}" />
    </inertial>
    <visual>
      <origin xyz="0.0 0.0 0.0" rpy="0 0 0"/>
      <geometry name="DWLExt_visual">
        <mesh filename="package://cogimon_urdf/meshes/TorsoRollExt.stl" scale="${mmTom} ${mmTom} ${mmTom}" />
      </geometry>
      <material name="green"/>
    </visual>
    <collision>
      <origin xyz="0.0 0.0 0.0" rpy="0 0 0"/>
      <geometry name="DWLExt_collision">
        <mesh filename="package://cogimon_urdf/meshes/simple/TorsoRollExt.stl" scale="${mmTom} ${mmTom} ${mmTom}" />
      </geometry>             
    </collision>
</link>

<link name ="DWYTorso">
    <inertial>
        <origin xyz="${-5.9646212e+01*mmTom} ${1.4305062*mmTom} ${4.2741527e+01*mmTom}" rpy="0 0 0"/>
        <mass value="1.2512295e+01"/>
      <inertia ixx="${2.1021617e+05*mm2Tom2}"  ixy="${-1.5527214e+02*mm2Tom2}"  ixz="${-5.0216602e+04*mm2Tom2}" iyy="${1.9982996e+05*mm2Tom2}" iyz="${-2.9204792e+02*mm2Tom2}" izz="${1.4025094e+05*mm2Tom2}" />
    </inertial>
    <visual>
      <origin xyz="0.0 0.0 0.0" rpy="0 0 0"/>
      <geometry name="DWYTorso_visual">
        <mesh filename="package://cogimon_urdf/meshes/Chest.stl" scale="${mmTom} ${mmTom} ${mmTom}" />
      </geometry>
      <material name="dark_grey"/>
    </visual>
    <collision>
      <origin xyz="0.0 0.0 0.0" rpy="0 0 0"/>
      <geometry name="DWYTorso_collision">
        <mesh filename="package://cogimon_urdf/meshes/simple/Chest.stl" scale="${mmTom} ${mmTom} ${mmTom}" />
      </geometry>             
    </collision>
</link>

<link name="torso"/>

</xacro:unless>

<!-- JOINTS -->
<joint name="WaistLat" type="revolute">
    <parent link="Waist"/>
    <child link="DWL"/>
    <origin xyz="${12.00*mmTom} 0.0 0.0" rpy="0 0 0" />
    <axis xyz="1 0 0" />
    <limit velocity="7.4" effort="140" lower="${-30.*toRad}" upper="${30.*toRad}" />
    <dynamics friction="0" damping="3.0"/>
</joint>

<xacro:if value="${COGIMON_PENNACCHIO}" >

<joint name="pennacchio_frame" type="fixed">
    <parent link="DWL"/>
    <child link="pennacchio"/>
    <origin xyz="${-54.0957*mmTom} 0.0 ${66.5*mmTom}" rpy="0 0 0" />
</joint>

<joint name="weight_frame" type="fixed">
    <parent link="pennacchio"/>
    <child link="weight"/>
    <origin xyz="0. 0. ${z}" rpy="0 0 0" />
</joint>

</xacro:if>

<xacro:unless value="${COGIMON_PENNACCHIO}">

<joint name="WaistFixed" type="fixed">
    <parent link="DWL"/>
    <child link="DWLExt"/>
    <origin xyz="${-54.0957*mmTom} 0.0 ${63.5*mmTom}" rpy="0 0 0" />
</joint>

<joint name="WaistYaw" type="revolute">
    <parent link="DWLExt"/>
    <child link="DWYTorso"/>
    <origin xyz="0 0 ${168.15*mmTom}" rpy="0 0 0" />
    <axis xyz="0 0 1" />
    <limit velocity="6.283" effort="120" lower="${-100.0*toRad}" upper="${100.0*toRad}" />
    <dynamics friction="0" damping="3.0"/>
</joint>

<joint name="torso_joint" type="fixed">
    <parent link="DWYTorso"/>
    <child link="torso"/>
    <origin xyz="0.0 0.0 ${155.126*mmTom}" rpy="0 0 0" />
</joint>

</xacro:unless>

</xacro:if>
</robot>
