<?xml version="1.0"?>
<robot xmlns:xacro="http://ros.org/wiki/xacro" name="cogimon">

<!-- 
  ROS urdf definition of the COGIMON humanoid robot by Istituto Italiano di Tecnologia
  
  DO NOT INCLUDE THIS FILE DIRECTLY! USE cogimon_robot.urdf.xacro INSTEAD!

  Author: Enrico Mingo

  Inertial matrix has to be in CoM frame (URDF specs)
-->

<!-- ************ SOME DEFS ********************** -->
<xacro:include filename="$(find cogimon_urdf)/urdf/conversions.urdf.xacro" />


<!-- ************ MODEL CONFIGURATION ************ -->
<xacro:include filename="$(find cogimon_urdf)/urdf/cogimon_config.urdf.xacro" />

<!-- ***********  MODEL COLORS *********** -->
<xacro:include filename="$(find cogimon_urdf)/urdf/cogimon_materials.urdf.xacro" />

<!-- Head -->
<!-- This links are defined in order to be compliant with http://www.ros.org/reps/rep-0120.html#coordinate-frames
and to define the end effectors of the robot.
The coordinate frame called gaze defines the head position and orientation. The orientation indicates in which direction the head appears to be looking regardless of any sensors (camera for instance). -->
<!--link name="gaze"/>

	<joint name="gaze_joint" type="fixed">
		<parent link="torso"/>
		<child link="gaze"/>
		<origin xyz="0 0 0.1" rpy="0 0 0" />
	</joint-->

        <!-- NECK -->
	<!--xacro:include filename="$(find cogimon_urdf)/urdf/parts/neck.urdf.xacro" /-->

<!-- ************ COGIMON BASE ************** -->
<xacro:include filename="$(find cogimon_urdf)/urdf/cogimon_base.urdf.xacro"/>

<!-- ************ REF FRAMES **************** -->
<xacro:include filename="$(find cogimon_urdf)/urdf/parts/feet_reference_frames.urdf.xacro"/>
<xacro:include filename="$(find cogimon_urdf)/urdf/parts/arms_reference_frames.urdf.xacro"/>

<xacro:if value="${COGIMON_FLOATING_BASE}" >
<link name="world"/>

  <joint name="reference" type="floating">
    <parent link="world"/>
    <child link="base_link"/>
</joint>
</xacro:if>

<xacro:if value="${COGIMON_FIXED_BASE}" >
  <link name="world"/>
  
   <joint name="fixed" type="fixed">
    <parent link="world"/>
    <child link="base_link"/>
  </joint>
</xacro:if>
  
</robot>




