<?xml version="1.0"?>
<robot xmlns:xacro="http://ros.org/wiki/xacro">

<xacro:if value="${COGIMON_HEAD}" >

<!-- LINKS -->
<link name ="Neck">
    <inertial>
      <origin xyz="${1.9525578e+01*mmTom} ${8.7785097e-02*mmTom} ${7.3374976e+01*mmTom} " rpy="0 0 0"/>
      <mass value="2.3794941e-01"/>
      <inertia ixx="${2.8460315e+02*mm2Tom2}"  ixy="${-5.4194691e-01*mm2Tom2}"  ixz="${-7.3250232e+01*mm2Tom2}" iyy="${4.5308750e+02*mm2Tom2}" iyz="${-9.4474115e-02*mm2Tom2}" izz="${2.7675534e+02*mm2Tom2}" />
    </inertial>
    <visual>
      <origin xyz="0.0 0.0 0.0" rpy="0 0 0"/>
      <geometry name="Neck_visual">
        <mesh filename="package://cogimon_urdf/meshes/NeckFixed.stl" scale="${mmTom} ${mmTom} ${mmTom}" />
      </geometry>
      <material name="dark_grey"/>
    </visual>
    <collision>
      <origin xyz="0.0 0.0 0.0" rpy="0 0 0"/>
      <geometry name="Neck_collision">
        <mesh filename="package://cogimon_urdf/meshes/simple/NeckFixed.stl" scale="${mmTom} ${mmTom} ${mmTom}" />
      </geometry>             
    </collision>
</link>

<link name ="HeadHokuyo"> <!-- TODO: CHECK THESE VALUES!!! -->
    <inertial>
      <origin xyz="${5.5322369e+01*mmTom} ${1.8472201e+01*mmTom} ${-1.8483703e+01*mmTom} " rpy="0 0 0"/>
      <mass value="5.4611797e-01"/>
      <inertia ixx="${1.9756996e+03*mm2Tom2}"  ixy="${-1.1287972e+02*mm2Tom2}"  ixz="${1.1284571e+02*mm2Tom2}" iyy="${4.4030675e+03*mm2Tom2}" iyz="${4.9540219e+02*mm2Tom2}" izz="${4.4027914e+03*mm2Tom2}" />
    </inertial>
    <visual>
      <origin xyz="0.0 0.0 0.0" rpy="${-45.0*toRad} 0 0"/>
      <geometry name="Neck_visual">
        <mesh filename="package://cogimon_urdf/meshes/HeadRoll.stl" scale="${mmTom} ${mmTom} ${mmTom}" />
      </geometry>
      <material name="dark_grey"/>
    </visual>
    <collision>
      <origin xyz="0.0 0.0 0.0" rpy="${-45.0*toRad} 0 0"/>
      <geometry name="Neck_collision">
        <mesh filename="package://cogimon_urdf/meshes/simple/HeadRoll.stl" scale="${mmTom} ${mmTom} ${mmTom}" />
      </geometry>             
    </collision>
</link>

<!-- JOINTS -->
<joint name="neck_frame" type="fixed">
    <parent link="DWYTorso"/>
    <child link="Neck"/>
    <origin xyz="${16.*mmTom} 0.0 ${196.5*mmTom}" rpy="0 0 0" />
</joint>

<xacro:if value="${COGIMON_LASER_FIXED}">
  <joint name="head_roll" type="fixed">
    <parent link="Neck"/>
    <child link="HeadHokuyo"/>
    <origin xyz="${49.6*mmTom} 0.0 ${90.*mmTom}" rpy="0 0 0" />
  </joint>
</xacro:if>
<xacro:unless value="${COGIMON_LASER_FIXED}">
  <joint name="head_roll" type="revolute">
    <parent link="Neck"/>
    <child link="HeadHokuyo"/>
    <origin xyz="${49.6*mmTom} 0.0 ${90.*mmTom}" rpy="0 0 0" />
    <axis xyz="1 0 0" />
    <limit velocity="6.283" effort="20" lower="-2.5" upper="2.5" /> <!-- TODO: CHECK THESE VALUES!!! -->
    <dynamics friction="0" damping="3.0"/>
  </joint>
</xacro:unless>

</xacro:if>
</robot>
